<?xml version="1.0" ?>
<sdf version="1.6">
  <model name="ur5_robot">
    <!-- links -->
    <link name="world">
      <visual name="visual">
        <geometry>
          <sphere>
            <radius>0.01</radius>
          </sphere>
        </geometry>
      </visual>
      <collision name="collision">
        <geometry>
          <sphere>
            <radius>0.01</radius>
          </sphere>
        </geometry>
      </collision>
      <inertial>
        <mass>1e-6</mass>
        <inertia>
          <ixx>1e-6</ixx>
          <ixy>0</ixy>
          <ixz>0</ixz>
          <iyy>1e-6</iyy>
          <iyz>0</iyz>
          <izz>1e-6</izz>
        </inertia>
      </inertial>
    </link>
    <link name="base_link"/>
    <link name="base_link_inertia">
      <!-- Insert visual, collision, and inertial properties from URDF -->
        <visual>
            <origin rpy="0 0 3.141592653589793" xyz="0 0 0" />
            <geometry>
                <mesh filename="package://ur_description/meshes/ur5/visual/base.dae" />
            </geometry>
            <material name="LightGrey">
                <color rgba="0.7 0.7 0.7 1.0" />
            </material>
        </visual>
        <collision>
            <origin rpy="0 0 3.141592653589793" xyz="0 0 0" />
            <geometry>
                <mesh filename="package://ur_description/meshes/ur5/collision/base.stl" />
            </geometry>
        </collision>
        <inertial>
            <mass value="4.0" />
            <origin rpy="0 0 0" xyz="0 0 0" />
            <inertia ixx="0.00443333156" ixy="0.0" ixz="0.0" iyy="0.00443333156" iyz="0.0" izz="0.0072" />
        </inertial>      
    </link>
    <link name="shoulder_link">
      <!-- Insert visual, collision, and inertial properties from URDF -->
        <visual>
            <origin rpy="0 0 3.141592653589793" xyz="0 0 0" />
            <geometry>
                <mesh filename="package://ur_description/meshes/ur5/visual/shoulder.dae" />
            </geometry>
            <material name="LightGrey">
                <color rgba="0.7 0.7 0.7 1.0" />
            </material>
        </visual>
        <collision>
            <origin rpy="0 0 3.141592653589793" xyz="0 0 0" />
            <geometry>
                <mesh filename="package://ur_description/meshes/ur5/collision/shoulder.stl" />
            </geometry>
        </collision>
        <inertial>
            <mass value="3.7" />
            <origin rpy="0 0 0" xyz="0 0 0" />
            <inertia ixx="0.014972352344389999" ixy="0.0" ixz="0.0" iyy="0.014972352344389999" iyz="0.0" izz="0.01040625" />
        </inertial>
    </link>
    <link name="upper_arm_link">
      <!-- Insert visual, collision, and inertial properties from URDF -->
        <visual>
            <origin rpy="1.5707963267948966 0 -1.5707963267948966" xyz="0 0 0.13585" />
            <geometry>
                <mesh filename="package://ur_description/meshes/ur5/visual/upperarm.dae" />
            </geometry>
            <material name="LightGrey">
                <color rgba="0.7 0.7 0.7 1.0" />
            </material>
        </visual>
        <collision>
            <origin rpy="1.5707963267948966 0 -1.5707963267948966" xyz="0 0 0.13585" />
            <geometry>
                <mesh filename="package://ur_description/meshes/ur5/collision/upperarm.stl" />
            </geometry>
        </collision>
        <inertial>
            <mass value="8.393" />
            <origin rpy="0 1.5707963267948966 0" xyz="-0.2125 0.0 0.136" />
            <inertia ixx="0.1338857818623325" ixy="0.0" ixz="0.0" iyy="0.1338857818623325" iyz="0.0" izz="0.0151074" />
        </inertial>
    </link>
    <link name="forearm_link">
      <!-- Insert visual, collision, and inertial properties from URDF -->
        <visual>
            <origin rpy="1.5707963267948966 0 -1.5707963267948966" xyz="0 0 0.0165" />
            <geometry>
                <mesh filename="package://ur_description/meshes/ur5/visual/forearm.dae" />
            </geometry>
            <material name="LightGrey">
                <color rgba="0.7 0.7 0.7 1.0" />
            </material>
        </visual>
        <collision>
            <origin rpy="1.5707963267948966 0 -1.5707963267948966" xyz="0 0 0.0165" />
            <geometry>
                <mesh filename="package://ur_description/meshes/ur5/collision/forearm.stl" />
            </geometry>
        </collision>
        <inertial>
            <mass value="2.275" />
            <origin rpy="0 1.5707963267948966 0" xyz="-0.196125 0.0 0.0165" />
            <inertia ixx="0.03121679102890359" ixy="0.0" ixz="0.0" iyy="0.03121679102890359" iyz="0.0" izz="0.004095" />
        </inertial>
    </link>
    <link name="wrist_1_link">
      <!-- Insert visual, collision, and inertial properties from URDF -->
        <visual>
            <!-- TODO: Move this to a parameter -->
            <origin rpy="1.5707963267948966 0 0" xyz="0 0 -0.093" />
            <geometry>
                <mesh filename="package://ur_description/meshes/ur5/visual/wrist1.dae" />
            </geometry>
            <material name="LightGrey">
                <color rgba="0.7 0.7 0.7 1.0" />
            </material>
        </visual>
        <collision>
            <origin rpy="1.5707963267948966 0 0" xyz="0 0 -0.093" />
            <geometry>
                <mesh filename="package://ur_description/meshes/ur5/collision/wrist1.stl" />
            </geometry>
        </collision>
        <inertial>
            <mass value="1.219" />
            <origin rpy="0 0 0" xyz="0 0 0" />
            <inertia ixx="0.0020138887777775" ixy="0.0" ixz="0.0" iyy="0.0020138887777775" iyz="0.0" izz="0.0021942" />
        </inertial>
    </link>
    <link name="wrist_2_link">
      <!-- Insert visual, collision, and inertial properties from URDF -->
        <visual>
            <origin rpy="0 0 0" xyz="0 0 -0.095" />
            <geometry>
                <mesh filename="package://ur_description/meshes/ur5/visual/wrist2.dae" />
            </geometry>
            <material name="LightGrey">
                <color rgba="0.7 0.7 0.7 1.0" />
            </material>
        </visual>
        <collision>
            <origin rpy="0 0 0" xyz="0 0 -0.095" />
            <geometry>
                <mesh filename="package://ur_description/meshes/ur5/collision/wrist2.stl" />
            </geometry>
        </collision>
        <inertial>
            <mass value="1.219" />
            <origin rpy="0 0 0" xyz="0 0 0" />
            <inertia ixx="0.0018310388509175" ixy="0.0" ixz="0.0" iyy="0.0018310388509175" iyz="0.0" izz="0.0021942" />
        </inertial>
    </link>
    <link name="wrist_3_link">
      <!-- Insert visual, collision, and inertial properties from URDF -->
        <visual>
            <origin rpy="1.5707963267948966 0 0" xyz="0 0 -0.0818" />
            <geometry>
                <mesh filename="package://ur_description/meshes/ur5/visual/wrist3.dae" />
            </geometry>
            <material name="LightGrey">
                <color rgba="0.7 0.7 0.7 1.0" />
            </material>
        </visual>
        <collision>
            <origin rpy="1.5707963267948966 0 0" xyz="0 0 -0.0818" />
            <geometry>
                <mesh filename="package://ur_description/meshes/ur5/collision/wrist3.stl" />
            </geometry>
        </collision>
        <inertial>
            <mass value="0.1879" />
            <origin rpy="0 0 0" xyz="0.0 0.0 -0.01525" />
            <inertia ixx="8.062472608343e-05" ixy="0.0" ixz="0.0" iyy="8.062472608343e-05" iyz="0.0" izz="0.0001321171875" />
        </inertial>
    </link>
    <link name="base"/>
    <link name="flange"/>
    <link name="tool0"/>
    <!-- joints -->
    <joint name="base_joint" type="fixed">
    	<parent link="world"/>
    	<child link="base_link"/>
    	<origin rpy="0 0 0" xyz="0.0 0.0 0.17"/>
    </joint>
    <joint name="base_link-base_link_inertia" type="fixed">
        <parent link="base_link" />
        <child link="base_link_inertia" />
        <!-- 'base_link' is REP-103 aligned (so X+ forward), while the internal
           frames of the robot/controller have X+ pointing backwards.
           Use the joint between 'base_link' and 'base_link_inertia' (a dummy
           link/frame) to introduce the necessary rotation over Z (of pi rad).
      -->
        <origin rpy="0 0 3.141592653589793" xyz="0 0 0" />
    </joint>
    <joint name="shoulder_pan_joint" type="revolute">
        <parent link="base_link_inertia" />
        <child link="shoulder_link" />
        <origin rpy="0 0 0" xyz="0 0 0.089159" />
        <axis xyz="0 0 1" />
        <limit effort="150.0" lower="-6.283185307179586" upper="6.283185307179586" velocity="3.141592653589793" />
        <dynamics damping="0" friction="0" />
    </joint>
    <joint name="shoulder_lift_joint" type="revolute">
        <parent link="shoulder_link" />
        <child link="upper_arm_link" />
        <origin rpy="1.570796327 0 0" xyz="0 0 0" />
        <axis xyz="0 0 1" />
        <limit effort="150.0" lower="-6.283185307179586" upper="6.283185307179586" velocity="3.141592653589793" />
        <dynamics damping="0" friction="0" />
    </joint>
    <joint name="elbow_joint" type="revolute">
        <parent link="upper_arm_link" />
        <child link="forearm_link" />
        <origin rpy="0 0 0" xyz="-0.425 0 0" />
        <axis xyz="0 0 1" />
        <limit effort="150.0" lower="-3.141592653589793" upper="3.141592653589793" velocity="3.141592653589793" />
        <dynamics damping="0" friction="0" />
    </joint>
    <joint name="wrist_1_joint" type="revolute">
        <parent link="forearm_link" />
        <child link="wrist_1_link" />
        <origin rpy="0 0 0" xyz="-0.39225 0 0.10915" />
        <axis xyz="0 0 1" />
        <limit effort="28.0" lower="-6.283185307179586" upper="6.283185307179586" velocity="3.141592653589793" />
        <dynamics damping="0" friction="0" />
    </joint>
    <joint name="wrist_2_joint" type="revolute">
        <parent link="wrist_1_link" />
        <child link="wrist_2_link" />
        <origin rpy="1.570796327 0 0" xyz="0 -0.09465 -1.941303950897609e-11" />
        <axis xyz="0 0 1" />
        <limit effort="28.0" lower="-6.283185307179586" upper="6.283185307179586" velocity="3.141592653589793" />
        <dynamics damping="0" friction="0" />
    </joint>
    <joint name="wrist_3_joint" type="revolute">
        <parent link="wrist_2_link" />
        <child link="wrist_3_link" />
        <origin rpy="1.570796326589793 3.141592653589793 3.141592653589793" xyz="0 0.0823 -1.688001216681175e-11" />
        <axis xyz="0 0 1" />
        <limit effort="28.0" lower="-6.283185307179586" upper="6.283185307179586" velocity="3.141592653589793" />
        <dynamics damping="0" friction="0" />
    </joint>
    <!--joint name="base_joint" type="fixed">
      <!-- Insert origin and parent/child link references from URDF -->
      <parent>world</parent>
      <child>base_link</child>
      <pose>0.0 0.0 0.17 0 0 0</pose>
    </joint>
    <joint name="base_link-base_link_inertia" type="fixed">
      <!-- Insert origin and parent/child link references from URDF -->
      <parent>base_link</parent>
      <child>base_link_inertia</child>
      <pose>0 0 0 0 0 3.141592653589793</pose>
    </joint>
    <!-- Insert other joint definitions from URDF -->
    <joint name='shoulder_pan_joint' type='revolute'>
      <parent>base_link_inertia</parent>
      <child>shoulder_link</child>
      <pose>0 0 0.089159 0 0 0</pose>
      <axis>
        <xyz>0 0 1</xyz>
      </axis>
      <limit>
        <lower>-6.283185307179586</lower>
        <upper>6.283185307179586</upper>
        <effort>150</effort>
        <velocity>3.141592653589793</velocity>
      </limit>
      <dynamics>
        <damping>0</damping>
        <friction>0</friction>
      </dynamics>
    </joint>
    <joint name='shoulder_lift_joint' type='revolute'>
      <parent>shoulder_link</parent>
      <child>upper_arm_link</child>
      <pose>0 0 0 1.570796327 0 0</pose>
      <axis>
        <xyz>0 0 1</xyz>
      </axis>
      <limit>
        <lower>-6.283185307179586</lower>
        <upper>6.283185307179586</upper>
        <effort>150</effort>
        <velocity>3.141592653589793</velocity>
      </limit>
      <dynamics>
        <damping>0</damping>
        <friction>0</friction>
      </dynamics>
    </joint>
    <joint name='elbow_joint' type='revolute'>
      <parent>upper_arm_link</parent>
      <child>forearm_link</child>
      <pose>-0.425 0 0 0 0 0</pose>
      <axis>
        <xyz>0 0 1</xyz>
      </axis>
      <limit>
        <lower>-3.141592653589793</lower>
        <upper>3.141592653589793</upper>
        <effort>150</effort>
        <velocity>3.141592653589793</velocity>
      </limit>
      <dynamics>
        <damping>0</damping>
        <friction>0</friction>
      </dynamics>
    </joint>
    <joint name='wrist_1_joint' type='revolute'>
      <parent>forearm_link</parent>
      <child>wrist_1_link</child>
      <pose>-0.39225 0 0.10915 0 0 0</pose>
      <axis>
        <xyz>0 0 1</xyz>
      </axis>
      <limit>
        <lower>-6.283185307179586</lower>
        <upper>6.283185307179586</upper>
        <effort>28</effort>
        <velocity>3.141592653589793</velocity>
      </limit>
      <dynamics>
        <damping>0</damping>
        <friction>0</friction>
      </dynamics>
    </joint>
    <joint name='wrist_2_joint' type='revolute'>
      <parent>wrist_1_link</parent>
      <child>wrist_2_link</child>
      <pose>0 -0.09465 -1.941303950897609e-11 1.570796327 0 0</pose>
      <axis>
        <xyz>0 0 1</xyz>
      </axis>
      <limit>
        <lower>-6.283185307179586</lower>
        <upper>6.283185307179586</upper>
        <effort>28</effort>
        <velocity>3.141592653589793</velocity>
      </limit>
      <dynamics>
        <damping>0</damping>
        <friction>0</friction>
      </dynamics>
    </joint>
    <joint name='wrist_3_joint' type='revolute'>
      <parent>wrist_2_link</parent>
      <child>wrist_3_link</child>
      <pose>0 0.0823 -1.688001216681175e-11 1.570796326589793 3.141592653589793 3.141592653589793</pose>
      <axis>
        <xyz>0 0 1</xyz>
      </axis>
      <limit>
        <lower>-6.283185307179586</lower>
        <upper>6.283185307179586</upper>
        <effort>28</effort>
        <velocity>3.141592653589793</velocity>
      </limit>
      <dynamics>
        <damping>0</damping>
        <friction>0</friction>
      </dynamics-->
    </joint>
    <!-- gazebo plugins -->
    <plugin name="gazebo_ros_control" filename="libgazebo_ros_control.so">
      <robotNamespace>/</robotNamespace>
    </plugin>
    <!-- self-collide settings -->
    <!-- Insert self-collide settings from URDF -->
    <gazebo reference="base_link">
      <selfCollide>true</selfCollide>
    </gazebo>
    <gazebo reference="shoulder_link">
      <selfCollide>true</selfCollide>
    </gazebo>
    <!-- Add similar self-collide properties for the remaining links in the URDF -->
    <gazebo reference="upper_arm_link">
    	<selfCollide>true</selfCollide>
    </gazebo>
    <gazebo reference="forearm_link">
    	<selfCollide>true</selfCollide>
    </gazebo>
    <gazebo reference="wrist_1_link">
    	<selfCollide>true</selfCollide>
    </gazebo>
    <gazebo reference="wrist_2_link">
    	<selfCollide>true</selfCollide>
    </gazebo>
    <gazebo reference="wrist_3_link">
    	<selfCollide>true</selfCollide>
    </gazebo>
  </model>
</sdf>